- [프로그램 오류](#프로그램-오류)
- [예외 클래스의 계층 구조](#예외-클래스의-계층-구조)
- [예외 처리하기 - try-catch문](#예외-처리하기---try-catch문)
- [예외의 발생과 catch블럭](#예외의-발생과-catch블럭)
- [printStackTrace()와 getMessage()](#printstacktrace와-getmessage)
  - [멀티 catch블럭](#멀티-catch블럭)
- [예외 발생시키기 - throw](#예외-발생시키기---throw)
- [메서드에 예외 선언하기 - throws](#메서드에-예외-선언하기---throws)
- [finally블럭](#finally블럭)
- [자동 자원 반환 - try-with-resources문](#자동-자원-반환---try-with-resources문)
- [사용자정의 예외 만들기](#사용자정의-예외-만들기)
- [예외 되던지기(exception re-throwing)](#예외-되던지기exception-re-throwing)
- [연결된 예외(chained exception)](#연결된-예외chained-exception)

---

# 프로그램 오류

에러

- 컴파일 에러
  - 컴파일 시에 발생되는 에러
- 런타임 에러
  - 실행 시에 발생하는 에러
- 논리적 에러
  - 실행은 되지만, 의도와 다르게 동작

실행 시 발생할 수 있는 프로그램 오류

- 에러(error)
  - 심각한 오류
  - 수습 불가
- 예외(exception)
  - 덜 심각한 오류
  - 수습 가능

---

# 예외 클래스의 계층 구조

Object

- Throwable
  - Error
    - LinkageError
    - ThreadDeath
    - VirualMachineError
  - **Exception**
    - InterruptedException
    - InstantiationException
    - NoSuchMethodException
    - CloneNotFoundException
    - CloneNotSupportedException
    - IllegalAccessException
    - IOException
    - RuntimeException
      - ArithmeticException
      - ClassCastException
      - NullPointException
      - IndexOutOfBoundException

---

# 예외 처리하기 - try-catch문

예외 처리(exception handling)

- 정의
  - 프로그램 실행 시 발생할 수 있는 예외에 대비한 코드 작성
- 목적
  - 프로그램의 비정상 종료 방지, 정상적인 실행상태 유지

```java
try{
    //예외 발생 가능성이 있는 문장들
}catch(Exception1 e1){
    //Exception1이 발생했을 때, 이를 처리하기 위한 문장
}catch(Exception2 e2){//예외 참조변수가 중복되면 안된다.
    //Exception2이 발생했을 때, 이를 처리하기 위한 문장
}
```

```java
package YJ;

public class YJ8_01 {

 public static void main(String[] args) {
  int number = 100;
  int result = 0;
  
  for(int i = 0; i < 10; i++) {
   try {
    result = number / (int)(Math.random() * 10);
    System.out.println(result);
   } catch (Exception e) {
    System.out.println("0");
   }
  }
 }

}

// <Console>
// 25
// 100
// 50
// 25
// 16
// 25
// 0 //예외처리
// 16
// 100
// 0 //예외처리

```

---

# 예외의 발생과 catch블럭

예외가 발생하면, 발생한 예외에 해당하는 클래스의 인스턴스가 만들어 진다.

- 만약 ArithmeticException이 발생하면, ArithmeticException인스턴스가 생성되는 것

```java
package YJ;
public class YJ8_07 {
 public static void main(String[] args) {
  System.out.println(1);
  System.out.println(2);
  
  try {
   System.out.println(3);
   System.out.println(0/0);
   System.out.println(4);
  } catch (ArithmeticException ae) {
   if(ae instanceof ArithmeticException)
    System.out.println("true");
   System.out.println("ArithmeticException");
  } catch (Exception e) {
   System.out.println("Exception");
  }
  System.out.println(6);
 }
}

// <Console>
// 1
// 2
// 3
// true
// ArithmeticException
// 6
```

---

# printStackTrace()와 getMessage()

- printStackTrace()
  - 예외발생 당시의 호출스택(Call Stack)에 있었던 메서드의 정보와 예외 메시지를 화면에 출력한다.
- getMessage()
  - 발생한 예외클래스의 인스턴스에 저장된 메시지를 얻을 수 있다.

```java
package YJ;
public class YJ8_08 {
 public static void main(String[] args) {
  System.out.println(1);
  System.out.println(2);
  
  try {
   System.out.println(3);
   System.out.println(0/0);
   System.out.println(4);
  } catch (ArithmeticException ae) {
   ae.printStackTrace();
   System.out.println("예외메시지: " + ae.getMessage());
  } catch (Exception e) {
   System.out.println("Exception");
  }
  System.out.println(6);
 }
}

// <Console>
// 1
// 2
// 3
// java.lang.ArithmeticException: / by zero
//  at YJ.YJ8_08.main(YJ8_08.java:9)
// 예외메시지: / by zero
// 6
```

## 멀티 catch블럭

여러 catch블럭을 '|'기호를 이용해서, 하나의 catch블럭으로 합칠 수 있게 되었다.

```java
try{
    ...
} catch (ExceptionA e) {
    e.printStackTrace();
} catch (ExceptionB e2) {
    e2.printStackTrace();
}
```

↓↓↓↓↓↓↓↓

```java
try{
    ...
} catch (ExceptionA | ExceptionB e) {
    e.printStackTrace();
}
```

만일 멀티 catch블럭의 '|'로 연결된 예외 클래스가 조상과 자손의 관계에 있다면 컴파일 에러가 발생한다.

- 두 예외 클래스가 조상과 자손의 관계라면, 그냥 조상 클래스만 써주는 것과 똑같기 때문이다.

```java
try {
    ...
} catch (ParentException | ChildException e) { //에러, ParentException e와 같다.
    e.printStackTrace();
}
```

---

# 예외 발생시키기 - throw

키워드 throw를 사용해서 프로그래머가 고의로 예외를 발생시킬 수 있다.

1. 연산자 new를 이용해서 발생시키려는 예외 클래스의 객체를 만든다.
   ```Exception e = new Exception("고의로 발생시켰음");```
2. 키워드 throw를 이용해서 예외를 발생시킨다.
   ```throw e;```

```java
package YJ;
public class YJ8_09 {
 public static void main(String[] args) {
  try {
   Exception e = new Exception("고의로 발생시켰음");//에러 발생
   throw e;//에러 던지기
   //throw new Exception("고의로 발생시켰음"); 위의 두 줄을 한 줄로 만들기
  } catch (Exception e) {
   System.out.println("에러메시지 :" + e.getMessage());
   e.printStackTrace();
  }
  System.out.println("프로그램이 정상 종료되었음.");
 }
}

// <Console>
// 에러메시지 :고의로 발생시켰음
// java.lang.Exception: 고의로 발생시켰음
//  at YJ.YJ8_09.main(YJ8_09.java:5)
// 프로그램이 정상 종료되었음.
```

- Exception인스턴스를 생성할 때, 생성자에 String을 넣어 주면, 이 String이 Exception인스턴스에 메시지로 저장된다.
  - 이 메시지는 getMessage()를 이용해서 얻을 수 있다.

checked예외

- Exception클래스들
- 컴파일러가 예외처리를 확인한다.

unchecked예외

- RuntimeException클래스들
- 컴파일러가 예외처리를 확인하지 않는다.

---

# 메서드에 예외 선언하기 - throws

메서드의 선언부에 키워드 throws를 사용해서 메서드 내에서 발생할 수 있는 예외를 적어준다.

```java
void method() throws Exception1, Exception2, Exception3, ..., ExceptionN{
    ...
}
```

모든 예외의 최고조상인 Exception클래스를 메서드에 선언하면, 이 메서드는 모든 종류의 예외가 발생할 가능성이 있다는 뜻이다.

```java
void method() throws Exception {
    ...
}
```

---

# finally블럭

finally블럭은 예외의 발생여부에 상관없이 실행되어야할 코드를 포함시킬 목적으로 사용된다.

```java
try {
    //예외 발생 가능성이 있는 문장
} catch (Exception1 e1) {
    //예외 처리를 위한 문장
} finally {
    //예외의 발생여부에 관계없이 항상 수행되어야 하는 문장들
}
```

```java
package YJ;
public class YJ8_19 {
 public static void main(String[] args) {
  YJ8_19.method1();
  System.out.println("method1()의 수행을 마치고 main메서드로 돌아왔습니다.");
 }
 
 static void method1() {
  try {
   System.out.println("method1()이 호출되었습니다.");
   return;
  } catch (Exception e) {
   e.printStackTrace();
  } finally {
   System.out.println("method1()의 finally블럭이 실행되었습니다.");
  }
 }

}

// <Console>
// method1()이 호출되었습니다.
// method1()의 finally블럭이 실행되었습니다.
// method1()의 수행을 마치고 main메서드로 돌아왔습니다.
```

---

# 자동 자원 반환 - try-with-resources문

주로 입출력에 사용되는 클래스 중에서는 사용한 후에 꼭 닫아 줘야 하는 것들이 있다.

- 그래야 사용했던 자원(resources)이 반환되기 때문이다.

```java
try {
    fis = new FileInputStream("score.dat");
    dis = new DataInputStream(fis);
    ...
} catch (IOException ie) {
    ie.printStackTrace();
} finally {
    dis.close(); //얘가 문제다. 예외 발생할 수 있음
}
```

↓↓↓↓↓↓↓↓↓

```java
try {
    fis = new FileInputStream("score.dat");
    dis = new DataInputStream(fis);
    ...
} catch (IOException ie) {
    ie.printStackTrace();
} finally {
    try {
        if(dis!=null)
            dis.close(); // 예외 처리
    } catch (IOException ie) {
        ie.printStackTrace();
    }
}
```

↓↓↓↓↓↓↓↓↓ try-with-resource문

```java
try (FileInputStream fis = new FileInputStream("score.dat");
    DataInputStream dis = new DataInputStream(fis) {
    while(true){
        score = dis.readInt();
        System.out.println(score);
        sum += score;
    }
} catch (IOException ie) {
    System.out.println("점수의 총합은 " + sum + "입니다.");
} catch (IOException ie) {
    ie.printStackTrace();
}
```

- try-with-resources문의 괄호()안에 객체를 생성하는 문장을 넣으면, 이 객체는 따로 close()를 호출하지 않아도 try블럭을 벗어나는 순간 자동적으로 close()가 호출된다.
- try블럭의 괄호() 안에 변수를 선언하는 것도 가능
  - 선언된 변수는 try블럭 내에서만 사용 가능
- 이처럼 try-with-resource문에 의해 자동으로 객체의 close()가 호출될 수 있으려면, 클래스가 AutoCloseable이라는 인터페이스를 구현한 것이어야 한다.

```java
public interface AutoCloseable{
    void close() throws Exception;
}
```

```java
package YJ;
public class YJ8_20 {
 public static void main(String[] args) {
  try (CloseableResource cr = new CloseableResource()) {//try블럭을 벗어나면서 close()호출
   cr.exceptionWork(false);//예외 발생하지 않는다.
  } catch(WorkException e) {
   e.printStackTrace();
  } catch(CloseException e) {
   e.printStackTrace();
  }
  System.out.println();
  
  try (CloseableResource cr = new CloseableResource()) {//try블럭을 벗어나면서 close()호출
   cr.exceptionWork(true);//두 예외가 동시에 발생할 수는 없기 때문에, 실제 발생한 예외를 WorkException으로 하고, CloseException은 억제된 예외로 다룬다.
  } catch(WorkException e) {
   e.printStackTrace();
  } catch(CloseException e) {
   e.printStackTrace();
  }//억제된 예외에 대한 정보는 실제로 발생한 예외인 WorkException에 저장된다.
 }
}

class CloseableResource implements AutoCloseable {
 public void exceptionWork(boolean exception) throws WorkException {
  System.out.println("exceptionWork(" + exception + ")가 호출됨");
  
  if(exception)
   throw new WorkException("WorkException발생!!!");
 }
 
 public void close() throws CloseException { //자동으로 호출된다.
  System.out.println("close()가 호출됨");
  throw new CloseException("CloseExcetpion발생!!!");
 }
}

class WorkException extends Exception {
 WorkException(String msg) { super(msg);}
}
class CloseException extends Exception {
 CloseException(String msg) { super(msg);}
}

// <Console>
// exceptionWork(false)가 호출됨
// close()가 호출됨
// YJ.CloseException: CloseExcetpion발생!!!
//  at YJ.CloseableResource.close(YJ8_20.java:33)
//  at YJ.YJ8_20.main(YJ8_20.java:6)

// exceptionWork(true)가 호출됨
// close()가 호출됨
// YJ.WorkException: WorkException발생!!!
//  at YJ.CloseableResource.exceptionWork(YJ8_20.java:28)
//  at YJ.YJ8_20.main(YJ8_20.java:14)
//  Suppressed: YJ.CloseException: CloseExcetpion발생!!!
//   at YJ.CloseableResource.close(YJ8_20.java:33)
//   at YJ.YJ8_20.main(YJ8_20.java:15)
```

- Throwable에는 억제된 예외와 관련된 다음과 같은 메서드가 정의되어 있다.
  - void addSuppressed(Throwable exception)
    - 억제된 예외를 추가
  - Throwable[] getSuppressed()
    - 억제된 예외(배열)를 반환

---

# 사용자정의 예외 만들기

보토에 Exception클래스 또는 RuntimeException클래스로부터 상속받아 클래스를 만들지만, 필요에 따라서 알맞은 예외 클래스를 선택할 수 있다.

- 가능하면 기존의 예외클래스를 사용하자.

```java
class MyException extends Exception {
    MyException(String msg) { //문자열을 매개변수로 받는 생성자
        super(msg); //조상인 Exception클래스의 생성자를 호출한다.
    }
}
```

```java
package YJ;
public class YJ8_21 {
 public static void main(String[] args) {
  try {
   startInstall();
   copyFiles();
  } catch (SpaceException e) {
   System.out.println("에러 메시지 : " + e.getMessage());
   e.printStackTrace();
   System.out.println("공간을 확보한 후에 다시 설치하시기 바랍니다.");
  } catch(MemoryException me) {
   System.out.println("에러 메시지 : " + me.getMessage());
   me.printStackTrace();
   System.gc(); //Garbage Collection을 수행하여 메모리를 늘려준다.
   System.out.println("다시 설치를 시도하세요."); 
  } finally {
   deleteTempFiles(); //프로그램 설치에 사용된 임시파일들을 삭제한다.
  }
 }


 static void startInstall() throws SpaceException, MemoryException {
  if(!enoughSpace())
   throw new SpaceException("설치할 공간이 부족합니다.");
  if(!enoughMemory())
   throw new MemoryException("메모리가 부족합니다.");
 }

 static void copyFiles() {}
 static void deleteTempFiles() {}

 static boolean enoughSpace() {
  return false;
 }

 static boolean enoughMemory() {
  return true;
 }
}

class SpaceException extends Exception {
 SpaceException(String msg){
  super(msg);
 }
}

class MemoryException extends Exception {
 MemoryException(String msg){
  super(msg);
 }
}

// <Console>
// 에러 메시지 : 설치할 공간이 부족합니다.
// YJ.SpaceException: 설치할 공간이 부족합니다.
//  at YJ.YJ8_21.startInstall(YJ8_21.java:24)
//  at YJ.YJ8_21.main(YJ8_21.java:5)
// 공간을 확보한 후에 다시 설치하시기 바랍니다.
```

---

# 예외 되던지기(exception re-throwing)

한 메서드에서 발생할 수 있는 예외가 여럿인 경우, 몇 개는 try-catch문을 통해서 메서드 내에서 자체적으로 처리하고, 그 나머지는 선언부에 지정하여 호출한 메서드에서 처리하도록 함으로써, 양쪽에 나눠서 처리되도록 할 수 있다.

- 단 하나의 예외를 양쪽에서 처리할 수도 있다.
- 예외가 발생할 메서드에서는 try-catch문을 사용해서 예외처리를 해줌과 동시에 메서드의 선언부에 발생할 예외를 throws에 지정해줘야 한다.

```java
package YJ;
public class YJ8_22 {
 public static void main(String[] args) {
  try {
   method1();
  } catch(Exception e) {
   System.out.println("main메서드에서 예외가 처리되었습니다.");
  }
 }
 
 static void method1() throws Exception{
  try {
   throw new Exception();
  }catch(Exception e) {
   System.out.println("method1메서드에서 예외가 처리되었습니다.");
   throw e;
  }
 }
}

// <Console>
// method1메서드에서 예외가 처리되었습니다.
// main메서드에서 예외가 처리되었습니다.
```

---

# 연결된 예외(chained exception)

한 예외가 다른 예외를 발생시킬 수동 있다.

- 예를 들어 예외 A가 예외 B를 발생시켰다면, A를 B의 '원인 예외(cause exception)'라고 한다.

```java
Throwable initCause(Throwable cause) 지정한 예외를 원인 예외로 등록
Throwable getCause() 원인 예외를 반환
```

```java
RuntimeException(Throwable cause)//원인예외를 등록하는 생성자
```

```java
try{
    startInstall(); //SpaceException 발생
    copyFiles();
} catch (SpaceException e) {
    InstallException ie = new InstallException("설치중 예외발생"); //예외 생성
    ie.initCause(e); //InstallException의 원인 예외를 SpaceException으로 지정
    throw ie; //InstallException을 발생시킨다.
} catch(MemoryException me){}
```

- 연결되 예외를 만드는 이유
  - 여러 예외를 하나의 큰 분류의 예외로 묶어서 다루기 위해
    - 조상으로 묶으면 실제로 어떤 예외가 발생한지 모른다.
  - checked예외를 unchecked예외로 바꿀 수 있도록 하기 위해서
    - 예외를 처리할 수 없는 상황에서 하지 않을 수 있다.
